<?xml version="1.0" ?>
<robot name="reactive_robot">

  <link name="base_link">
    <visual>
      <geometry><cylinder radius="0.15" length="0.1"/></geometry>
      <material name="blue"><color rgba="0 0 1 1"/></material>
    </visual>
    <collision>
      <geometry><cylinder radius="0.15" length="0.1"/></geometry>
    </collision>
    <inertial>
      <mass value="2.0"/>
      <inertia ixx="0.01" ixy="0.0" ixz="0.0" iyy="0.01" iyz="0.0" izz="0.02"/>
    </inertial>
  </link>

  <link name="left_wheel">
    <visual><geometry><cylinder radius="0.05" length="0.02"/></geometry></visual>
    <collision><geometry><cylinder radius="0.05" length="0.02"/></geometry></collision>
    <inertial><mass value="0.2"/><inertia ixx="0.001" ixy="0" ixz="0" iyy="0.001" iyz="0" izz="0.001"/></inertial>
  </link>
  <joint name="left_wheel_joint" type="continuous">
    <parent link="base_link"/>
    <child link="left_wheel"/>
    <origin xyz="0 0.16 -0.05" rpy="-1.5708 0 0"/>
    <axis xyz="0 0 1"/>
  </joint>

  <link name="right_wheel">
    <visual><geometry><cylinder radius="0.05" length="0.02"/></geometry></visual>
    <collision><geometry><cylinder radius="0.05" length="0.02"/></geometry></collision>
    <inertial><mass value="0.2"/><inertia ixx="0.001" ixy="0" ixz="0" iyy="0.001" iyz="0" izz="0.001"/></inertial>
  </link>
  <joint name="right_wheel_joint" type="continuous">
    <parent link="base_link"/>
    <child link="right_wheel"/>
    <origin xyz="0 -0.16 -0.05" rpy="-1.5708 0 0"/>
    <axis xyz="0 0 1"/>
  </joint>

  <link name="caster">
    <visual><geometry><sphere radius="0.05"/></geometry></visual>
    <collision><geometry><sphere radius="0.05"/></geometry></collision>
    <inertial><mass value="0.1"/><inertia ixx="0.001" ixy="0" ixz="0" iyy="0.001" iyz="0" izz="0.001"/></inertial>
  </link>
  <joint name="caster_joint" type="fixed">
    <parent link="base_link"/>
    <child link="caster"/>
    <origin xyz="0.1 0 -0.05" rpy="0 0 0"/>
  </joint>

  <link name="rear_caster">
    <visual><geometry><sphere radius="0.05"/></geometry></visual>
    <collision><geometry><sphere radius="0.05"/></geometry></collision>
    <inertial><mass value="0.1"/><inertia ixx="0.001" ixy="0" ixz="0" iyy="0.001" iyz="0" izz="0.001"/></inertial>
  </link>
  <joint name="rear_caster_joint" type="fixed">
    <parent link="base_link"/>
    <child link="rear_caster"/>
    <origin xyz="-0.1 0 -0.05" rpy="0 0 0"/>
  </joint>

  <link name="lidar_link">
    <visual><geometry><cylinder radius="0.04" length="0.05"/></geometry></visual>
  </link>
  <joint name="lidar_joint" type="fixed">
    <parent link="base_link"/>
    <child link="lidar_link"/>
    <origin xyz="0 0 0.075" rpy="0 0 0"/>
  </joint>

  <gazebo reference="caster">
    <mu1>0.0</mu1>
    <mu2>0.0</mu2>
  </gazebo>
  <gazebo reference="rear_caster">
    <mu1>0.0</mu1>
    <mu2>0.0</mu2>
  </gazebo>

  <gazebo>
    <plugin filename="gz-sim-diff-drive-system" name="gz::sim::systems::DiffDrive">
      <left_joint>left_wheel_joint</left_joint>
      <right_joint>right_wheel_joint</right_joint>
      <wheel_separation>0.32</wheel_separation>
      <wheel_radius>0.05</wheel_radius>
      <odom_publish_frequency>50</odom_publish_frequency>
      <topic>cmd_vel</topic>
    </plugin>
  </gazebo>

  <gazebo reference="lidar_link">
    <sensor name="lidar" type="gpu_lidar">
      <pose>0 0 0 0 0 0</pose>
      <topic>scan</topic>
      <update_rate>10</update_rate>
      <ray>
        <scan>
          <horizontal>
            <samples>360</samples>
            <resolution>1</resolution>
            <min_angle>-3.14159</min_angle>
            <max_angle>3.14159</max_angle>
          </horizontal>
        </scan>
        <range>
          <min>0.15</min>
          <max>8.0</max>
          <resolution>0.01</resolution>
        </range>
      </ray>
      <always_on>1</always_on>
      <visualize>true</visualize>
    </sensor>
  </gazebo>

</robot>